Workbook

Sheet Summery
A2: GLASSWARES ARC PROPOSAL 2024-25 | F2: 45390
A3: Sr No. | C3: Tentative Purchase | D3: Tentative saving | E3: Tentative Saving % | F3: Remark
A4: 1 | B4: Tharmo | C4: =Sheet1!AB182 -> 9089278.6 | D4: =Sheet1!V182 -> 4146369.4 | E4: =D4/C4 -> 0.45618246
A5: 2 | B5: J-SIL | C5: =Sheet1!AC182 -> 7603604.5 | D5: =Sheet1!X182 -> 5632043.5 | E5: =D5/C5 -> 0.74070707
A6: 3 | B6: Dodal | C6: =Sheet1!Z182 -> 13235648 | D6: 500000 | E6: =D6/C6 -> 0.037776768

Sheet Sheet1
E1: Santosh enterprises-Quoted rate 2024-25 | I1: Global Pharma Solution -Quoted rate -2024-25 | M1: J-SIL vs Thermo | N1: Dodal Enterprises- Quoted rate 2023-24 | R1: J-SIL vs Borosil | AA1: Turnover considering make on the basis of last year consumption (2023-24)
A2: Sr No. | B2: Cat No. | C2: Item Name | D2: Unit Qty. | E2: Unit price | F2: Discount % | G2: Disc. Inr | H2: Final net rate | I2: Unit price | J2: Discount % | K2: Disc. Inr | L2: Final net rate | M2: Saving in % | N2: Unit price | O2: Discount % | P2: Disc. Inr | Q2: Final net rate | R2: Saving in % | S2: Minium Rate | T2: Vendor Name | U2: RatD VaraincD ThDrmo | V2: Saving form Tharmao | W2: RatD VaraincD J-Sil | X2: Saving form J-SIL | Z2: Dodal- 23-24 | AA2: Dodal- 24-25 | AB2: Tharmo-24-25 | AC2: J-SIL-24-25
A3: 1 | B3: 5647005D | C3: VOLUMETRIC FLASK A CLASS CLEAR USP 5ML | D3: 100 | E3: 510 | F3: 0.35 | G3: =E3*F3 -> 178.5 | H3: =E3-G3 -> 331.5 | I3: 1084 | J3: 0.53 | K3: =I3*J3 -> 574.52 | L3: =I3-K3 -> 509.48 | M3: =(L3-H3)*100/L3 -> 34.933658 | N3: 1070 | O3: 0.36 | P3: =N3*O3 -> 385.2 | Q3: =N3-P3 -> 684.8 | R3: =(Q3-H3)*100/Q3 -> 51.591706 | S3: =MIN(H3,L3,Q3) -> 331.5 | T3: Santosh Enterprises | U3: =Q3-L3 -> 175.32 | V3: =U3*D3 -> 17532 | W3: =Q3-H3 -> 353.3 | X3: =W3*D3 -> 35330 | Z3: =Q3*D3 -> 68480 | AA3: 64200 | AB3: =L3*D3 -> 50948 | AC3: =H3*D3 -> 33150
A4: 2 | B4: 5655005 | C4: VOLUMETRIC FLASK A CLASS AMBER USP 5ML | D4: 100 | E4: 770 | F4: 0.35 | G4: =E4*F4 -> 269.5 | H4: =E4-G4 -> 500.5 | I4: 1326 | J4: 0.53 | K4: =I4*J4 -> 702.78 | L4: =I4-K4 -> 623.22 | M4: =(L4-H4)*100/L4 -> 19.691281 | N4: 1340 | O4: 0.36 | P4: =N4*O4 -> 482.4 | Q4: =N4-P4 -> 857.6 | R4: =(Q4-H4)*100/Q4 -> 41.639459 | S4: =MIN(H4,L4,Q4) -> 500.5 | T4: Santosh Enterprises | U4: =Q4-L4 -> 234.38 | V4: =U4*D4 -> 23438 | W4: =Q4-H4 -> 357.1 | X4: =W4*D4 -> 35710 | Z4: =Q4*D4 -> 85760 | AA4: 80400 | AB4: =L4*D4 -> 62322 | AC4: =H4*D4 -> 50050
A5: 3 | B5: 5647006D | C5: VOLUMETRIC FLASK A CLASS CLEAR USP 10ML | D5: 1000 | E5: 510 | F5: 0.35 | G5: =E5*F5 -> 178.5 | H5: =E5-G5 -> 331.5 | I5: 937.5 | J5: 0.53 | K5: =I5*J5 -> 496.875 | L5: =I5-K5 -> 440.625 | M5: =(L5-H5)*100/L5 -> 24.765957 | N5: 925 | O5: 0.36 | P5: =N5*O5 -> 333 | Q5: =N5-P5 -> 592 | R5: =(Q5-H5)*100/Q5 -> 44.003378 | S5: =MIN(H5,L5,Q5) -> 331.5 | T5: Santosh Enterprises | U5: =Q5-L5 -> 151.375 | V5: =U5*D5 -> 151375 | W5: =Q5-H5 -> 260.5 | X5: =W5*D5 -> 260500 | Z5: =Q5*D5 -> 592000 | AA5: 555000 | AB5: =L5*D5 -> 440625 | AC5: =H5*D5 -> 331500
A6: 4 | B6: 5655006 | C6: VOLUMETRIC FLASK A CLASS AMBER USP 10ML | D6: 500 | E6: 770 | F6: 0.35 | G6: =E6*F6 -> 269.5 | H6: =E6-G6 -> 500.5 | I6: 1131.5 | J6: 0.53 | K6: =I6*J6 -> 599.695 | L6: =I6-K6 -> 531.805 | M6: =(L6-H6)*100/L6 -> 5.8865562 | N6: 1175 | O6: 0.36 | P6: =N6*O6 -> 423 | Q6: =N6-P6 -> 752 | R6: =(Q6-H6)*100/Q6 -> 33.444149 | S6: =MIN(H6,L6,Q6) -> 500.5 | T6: Global Pharma | U6: =Q6-L6 -> 220.195 | V6: =U6*D6 -> 110097.5 | W6: =Q6-H6 -> 251.5 | X6: =W6*D6 -> 125750 | Z6: =Q6*D6 -> 376000 | AA6: 352500 | AB6: =L6*D6 -> 265902.5 | AC6: =H6*D6 -> 250250
A7: 5 | B7: 5647008D | C7: VOLUMETRIC FLASK A CLASS CLEAR USP 20ML | D7: 500 | E7: 550 | F7: 0.35 | G7: =E7*F7 -> 192.5 | H7: =E7-G7 -> 357.5 | I7: 942.5 | J7: 0.53 | K7: =I7*J7 -> 499.525 | L7: =I7-K7 -> 442.975 | M7: =(L7-H7)*100/L7 -> 19.295671 | N7: 925 | O7: 0.36 | P7: =N7*O7 -> 333 | Q7: =N7-P7 -> 592 | R7: =(Q7-H7)*100/Q7 -> 39.611486 | S7: =MIN(H7,L7,Q7) -> 357.5 | T7: Santosh Enterprises | U7: =Q7-L7 -> 149.025 | V7: =U7*D7 -> 74512.5 | W7: =Q7-H7 -> 234.5 | X7: =W7*D7 -> 117250 | Z7: =Q7*D7 -> 296000 | AA7: 277500 | AB7: =L7*D7 -> 221487.5 | AC7: =H7*D7 -> 178750
A8: 6 | B8: 5655008 | C8: VOLUMETRIC FLASK A CLASS AMBER USP 20ML | D8: 500 | E8: 750 | F8: 0.35 | G8: =E8*F8 -> 262.5 | H8: =E8-G8 -> 487.5 | I8: 1131.5 | J8: 0.53 | K8: =I8*J8 -> 599.695 | L8: =I8-K8 -> 531.805 | M8: =(L8-H8)*100/L8 -> 8.3310612 | N8: 1175 | O8: 0.36 | P8: =N8*O8 -> 423 | Q8: =N8-P8 -> 752 | R8: =(Q8-H8)*100/Q8 -> 35.172872 | S8: =MIN(H8,L8,Q8) -> 487.5 | T8: Santosh Enterprises | U8: =Q8-L8 -> 220.195 | V8: =U8*D8 -> 110097.5 | W8: =Q8-H8 -> 264.5 | X8: =W8*D8 -> 132250 | Z8: =Q8*D8 -> 376000 | AA8: 352500 | AB8: =L8*D8 -> 265902.5 | AC8: =H8*D8 -> 243750
A9: 7 | B9: 5647012D | C9: VOLUMETRIC FLASK A CLASS CLEAR USP 50ML | D9: 500 | E9: 540 | F9: 0.35 | G9: =E9*F9 -> 189 | H9: =E9-G9 -> 351 | I9: 826 | J9: 0.53 | K9: =I9*J9 -> 437.78 | L9: =I9-K9 -> 388.22 | M9: =(L9-H9)*100/L9 -> 9.5873474 | N9: 1000 | O9: 0.36 | P9: =N9*O9 -> 360 | Q9: =N9-P9 -> 640 | R9: =(Q9-H9)*100/Q9 -> 45.15625 | S9: =MIN(H9,L9,Q9) -> 351 | T9: Santosh Enterprises | U9: =Q9-L9 -> 251.78 | V9: =U9*D9 -> 125890 | W9: =Q9-H9 -> 289 | X9: =W9*D9 -> 144500 | Z9: =Q9*D9 -> 320000 | AA9: 300000 | AB9: =L9*D9 -> 194110 | AC9: =H9*D9 -> 175500
A10: 8 | B10: 5655012 | C10: VOLUMETRIC FLASK A CLASS AMBER USP 50ML | D10: 500 | E10: 740 | F10: 0.35 | G10: =E10*F10 -> 259 | H10: =E10-G10 -> 481 | I10: 1004.5 | J10: 0.53 | K10: =I10*J10 -> 532.385 | L10: =I10-K10 -> 472.115 | M10: =(L10-H10)*100/L10 -> -1.8819567 | N10: 1040 | O10: 0.36 | P10: =N10*O10 -> 374.4 | Q10: =N10-P10 -> 665.6 | R10: =(Q10-H10)*100/Q10 -> 27.734375 | S10: =MIN(H10,L10,Q10) -> 472.115 | T10: Global Pharma | U10: =Q10-L10 -> 193.485 | V10: =U10*D10 -> 96742.5 | W10: =Q10-H10 -> 184.6 | X10: =W10*D10 -> 92300 | Z10: =Q10*D10 -> 332800 | AA10: 312000 | AB10: =L10*D10 -> 236057.5 | AC10: =H10*D10 -> 240500
A11: 9 | B11: 5647016D | C11: VOLUMETRIC FLASK A CLASS CLEAR USP 100ML | D11: 1000 | E11: 550 | F11: 0.35 | G11: =E11*F11 -> 192.5 | H11: =E11-G11 -> 357.5 | I11: 810 | J11: 0.53 | K11: =I11*J11 -> 429.3 | L11: =I11-K11 -> 380.7 | M11: =(L11-H11)*100/L11 -> 6.0940373 | N11: 1050 | O11: 0.36 | P11: =N11*O11 -> 378 | Q11: =N11-P11 -> 672 | R11: =(Q11-H11)*100/Q11 -> 46.800595 | S11: =MIN(H11,L11,Q11) -> 357.5 | T11: Global Pharma | U11: =Q11-L11 -> 291.3 | V11: =U11*D11 -> 291300 | W11: =Q11-H11 -> 314.5 | X11: =W11*D11 -> 314500 | Z11: =Q11*D11 -> 672000 | AA11: 630000 | AB11: =L11*D11 -> 380700 | AC11: =H11*D11 -> 357500
A12: 10 | B12: 5655016 | C12: VOLUMETRIC FLASK A CLASS AMBER USP 100ML | D12: 500 | E12: 750 | F12: 0.35 | G12: =E12*F12 -> 262.5 | H12: =E12-G12 -> 487.5 | I12: 1002 | J12: 0.53 | K12: =I12*J12 -> 531.06 | L12: =I12-K12 -> 470.94 | M12: =(L12-H12)*100/L12 -> -3.5163715 | N12: 1015 | O12: 0.36 | P12: =N12*O12 -> 365.4 | Q12: =N12-P12 -> 649.6 | R12: =(Q12-H12)*100/Q12 -> 24.953818 | S12: =MIN(H12,L12,Q12) -> 470.94 | T12: Global Pharma | U12: =Q12-L12 -> 178.66 | V12: =U12*D12 -> 89330 | W12: =Q12-H12 -> 162.1 | X12: =W12*D12 -> 81050 | Z12: =Q12*D12 -> 324800 | AA12: 304500 | AB12: =L12*D12 -> 235470 | AC12: =H12*D12 -> 243750
A13: 11 | B13: 5647020D | C13: VOLUMETRIC FLASK A CLASS CLEAR USP 200ML | D13: 100 | E13: 750 | F13: 0.35 | G13: =E13*F13 -> 262.5 | H13: =E13-G13 -> 487.5 | I13: 1131.5 | J13: 0.53 | K13: =I13*J13 -> 599.695 | L13: =I13-K13 -> 531.805 | M13: =(L13-H13)*100/L13 -> 8.3310612 | N13: 1235 | O13: 0.36 | P13: =N13*O13 -> 444.6 | Q13: =N13-P13 -> 790.4 | R13: =(Q13-H13)*100/Q13 -> 38.322368 | S13: =MIN(H13,L13,Q13) -> 487.5 | T13: Santosh Enterprises | U13: =Q13-L13 -> 258.595 | V13: =U13*D13 -> 25859.5 | W13: =Q13-H13 -> 302.9 | X13: =W13*D13 -> 30290 | Z13: =Q13*D13 -> 79040 | AA13: 74100 | AB13: =L13*D13 -> 53180.5 | AC13: =H13*D13 -> 48750
A14: 12 | B14: 5655020 | C14: VOLUMETRIC FLASK A CLASS AMBER USP 200ML | D14: 50 | E14: 910 | F14: 0.35 | G14: =E14*F14 -> 318.5 | H14: =E14-G14 -> 591.5 | I14: 1383.5 | J14: 0.53 | K14: =I14*J14 -> 733.255 | L14: =I14-K14 -> 650.245 | M14: =(L14-H14)*100/L14 -> 9.0342871 | N14: 1435 | O14: 0.36 | P14: =N14*O14 -> 516.6 | Q14: =N14-P14 -> 918.4 | R14: =(Q14-H14)*100/Q14 -> 35.594512 | S14: =MIN(H14,L14,Q14) -> 591.5 | T14: Santosh Enterprises | U14: =Q14-L14 -> 268.155 | V14: =U14*D14 -> 13407.75 | W14: =Q14-H14 -> 326.9 | X14: =W14*D14 -> 16345 | Z14: =Q14*D14 -> 45920 | AA14: 43050 | AB14: =L14*D14 -> 32512.25 | AC14: =H14*D14 -> 29575
A15: 13 | B15: 5647021D | C15: VOLUMETRIC FLASK A CLASS CLEAR USP 250ML | D15: 100 | E15: 760 | F15: 0.35 | G15: =E15*F15 -> 266 | H15: =E15-G15 -> 494 | I15: 1137 | J15: 0.53 | K15: =I15*J15 -> 602.61 | L15: =I15-K15 -> 534.39 | M15: =(L15-H15)*100/L15 -> 7.5581504 | N15: 1330 | O15: 0.36 | P15: =N15*O15 -> 478.8 | Q15: =N15-P15 -> 851.2 | R15: =(Q15-H15)*100/Q15 -> 41.964286 | S15: =MIN(H15,L15,Q15) -> 494 | T15: Santosh Enterprises | U15: =Q15-L15 -> 316.81 | V15: =U15*D15 -> 31681 | W15: =Q15-H15 -> 357.2 | X15: =W15*D15 -> 35720 | Z15: =Q15*D15 -> 85120 | AA15: 79800 | AB15: =L15*D15 -> 53439 | AC15: =H15*D15 -> 49400
A16: 14 | B16: 5655021 | C16: VOLUMETRIC FLASK A CLASS AMBER USP 250ML | D16: 50 | E16: 935 | F16: 0.35 | G16: =E16*F16 -> 327.25 | H16: =E16-G16 -> 607.75 | I16: 1388.5 | J16: 0.53 | K16: =I16*J16 -> 735.905 | L16: =I16-K16 -> 652.595 | M16: =(L16-H16)*100/L16 -> 6.8717964 | N16: 1440 | O16: 0.36 | P16: =N16*O16 -> 518.4 | Q16: =N16-P16 -> 921.6 | R16: =(Q16-H16)*100/Q16 -> 34.054905 | S16: =MIN(H16,L16,Q16) -> 607.75 | T16: Global Pharma | U16: =Q16-L16 -> 269.005 | V16: =U16*D16 -> 13450.25 | W16: =Q16-H16 -> 313.85 | X16: =W16*D16 -> 15692.5 | Z16: =Q16*D16 -> 46080 | AA16: 43200 | AB16: =L16*D16 -> 32629.75 | AC16: =H16*D16 -> 30387.5
A17: 15 | B17: 5647024D | C17: VOLUMETRIC FLASK A CLASS CLEAR USP 500ML | D17: 100 | E17: 960 | F17: 0.35 | G17: =E17*F17 -> 336 | H17: =E17-G17 -> 624 | I17: 1499 | J17: 0.53 | K17: =I17*J17 -> 794.47 | L17: =I17-K17 -> 704.53 | M17: =(L17-H17)*100/L17 -> 11.430315 | N17: 1655 | O17: 0.36 | P17: =N17*O17 -> 595.8 | Q17: =N17-P17 -> 1059.2 | R17: =(Q17-H17)*100/Q17 -> 41.087613 | S17: =MIN(H17,L17,Q17) -> 624 | T17: Santosh Enterprises | U17: =Q17-L17 -> 354.67 | V17: =U17*D17 -> 35467 | W17: =Q17-H17 -> 435.2 | X17: =W17*D17 -> 43520 | Z17: =Q17*D17 -> 105920 | AA17: 99300 | AB17: =L17*D17 -> 70453 | AC17: =H17*D17 -> 62400
A18: 16 | B18: 5655024 | C18: VOLUMETRIC FLASK A CLASS AMBER USP 500ML | D18: 50 | E18: 1310 | F18: 0.35 | G18: =E18*F18 -> 458.5 | H18: =E18-G18 -> 851.5 | I18: 1830 | J18: 0.53 | K18: =I18*J18 -> 969.9 | L18: =I18-K18 -> 860.1 | M18: =(L18-H18)*100/L18 -> 0.99988373 | N18: 1895 | O18: 0.36 | P18: =N18*O18 -> 682.2 | Q18: =N18-P18 -> 1212.8 | R18: =(Q18-H18)*100/Q18 -> 29.790567 | S18: =MIN(H18,L18,Q18) -> 851.5 | T18: Global Pharma | U18: =Q18-L18 -> 352.7 | V18: =U18*D18 -> 17635 | W18: =Q18-H18 -> 361.3 | X18: =W18*D18 -> 18065 | Z18: =Q18*D18 -> 60640 | AA18: 56850 | AB18: =L18*D18 -> 43005 | AC18: =H18*D18 -> 42575
A19: 17 | B19: 5647029D | C19: VOLUMETRIC FLASK A CLASS CLEAR USP 1000ML | D19: 200 | E19: 1410 | F19: 0.35 | G19: =E19*F19 -> 493.5 | H19: =E19-G19 -> 916.5 | I19: 2182 | J19: 0.53 | K19: =I19*J19 -> 1156.46 | L19: =I19-K19 -> 1025.54 | M19: =(L19-H19)*100/L19 -> 10.632447 | N19: 2400 | O19: 0.36 | P19: =N19*O19 -> 864 | Q19: =N19-P19 -> 1536 | R19: =(Q19-H19)*100/Q19 -> 40.332031 | S19: =MIN(H19,L19,Q19) -> 916.5 | T19: Santosh Enterprises | U19: =Q19-L19 -> 510.46 | V19: =U19*D19 -> 102092 | W19: =Q19-H19 -> 619.5 | X19: =W19*D19 -> 123900 | Z19: =Q19*D19 -> 307200 | AA19: 288000 | AB19: =L19*D19 -> 205108 | AC19: =H19*D19 -> 183300
A20: 18 | B20: 5655029 | C20: VOLUMETRIC FLASK A CLASS AMBER USP 1000ML | D20: 100 | E20: 1790 | F20: 0.35 | G20: =E20*F20 -> 626.5 | H20: =E20-G20 -> 1163.5 | I20: 2667 | J20: 0.53 | K20: =I20*J20 -> 1413.51 | L20: =I20-K20 -> 1253.49 | M20: =(L20-H20)*100/L20 -> 7.1791558 | N20: 2765 | O20: 0.36 | P20: =N20*O20 -> 995.4 | Q20: =N20-P20 -> 1769.6 | R20: =(Q20-H20)*100/Q20 -> 34.250678 | S20: =MIN(H20,L20,Q20) -> 1163.5 | T20: Santosh Enterprises | U20: =Q20-L20 -> 516.11 | V20: =U20*D20 -> 51611 | W20: =Q20-H20 -> 606.1 | X20: =W20*D20 -> 60610 | Z20: =Q20*D20 -> 176960 | AA20: 165900 | AB20: =L20*D20 -> 125349 | AC20: =H20*D20 -> 116350
A21: 19 | B21: 7101001 | C21: VOLUMETRIC PIPETTE 1ML CLASS "A"USP | D21: 100 | E21: 290 | F21: 0.35 | G21: =E21*F21 -> 101.5 | H21: =E21-G21 -> 188.5 | I21: 399.1 | J21: 0.53 | K21: =I21*J21 -> 211.523 | L21: =I21-K21 -> 187.577 | M21: =(L21-H21)*100/L21 -> -0.49206459 | N21: 415 | O21: 0.36 | P21: =N21*O21 -> 149.4 | Q21: =N21-P21 -> 265.6 | R21: =(Q21-H21)*100/Q21 -> 29.028614 | S21: =MIN(H21,L21,Q21) -> 187.577 | T21: Global Pharma | U21: =Q21-L21 -> 78.023 | V21: =U21*D21 -> 7802.3 | W21: =Q21-H21 -> 77.1 | X21: =W21*D21 -> 7710 | Z21: =Q21*D21 -> 26560 | AA21: 24900 | AB21: =L21*D21 -> 18757.7 | AC21: =H21*D21 -> 18850
A22: 20 | B22: 7101002 | C22: VOLUMETRIC PIPETTE 2ML CLASS "A"USP | D22: 100 | E22: 300 | F22: 0.35 | G22: =E22*F22 -> 105 | H22: =E22-G22 -> 195 | I22: 448.2 | J22: 0.53 | K22: =I22*J22 -> 237.546 | L22: =I22-K22 -> 210.654 | M22: =(L22-H22)*100/L22 -> 7.431143 | N22: 465 | O22: 0.36 | P22: =N22*O22 -> 167.4 | Q22: =N22-P22 -> 297.6 | R22: =(Q22-H22)*100/Q22 -> 34.475806 | S22: =MIN(H22,L22,Q22) -> 195 | T22: Santosh Enterprises | U22: =Q22-L22 -> 86.946 | V22: =U22*D22 -> 8694.6 | W22: =Q22-H22 -> 102.6 | X22: =W22*D22 -> 10260 | Z22: =Q22*D22 -> 29760 | AA22: 27900 | AB22: =L22*D22 -> 21065.4 | AC22: =H22*D22 -> 19500
A23: 21 | B23: 7101003 | C23: VOLUMETRIC PIPETTE 3ML CLASS "A"USP | D23: 100 | E23: 350 | F23: 0.35 | G23: =E23*F23 -> 122.5 | H23: =E23-G23 -> 227.5 | I23: 473.5 | J23: 0.53 | K23: =I23*J23 -> 250.955 | L23: =I23-K23 -> 222.545 | M23: =(L23-H23)*100/L23 -> -2.226516 | N23: 490 | O23: 0.36 | P23: =N23*O23 -> 176.4 | Q23: =N23-P23 -> 313.6 | R23: =(Q23-H23)*100/Q23 -> 27.455357 | S23: =MIN(H23,L23,Q23) -> 222.545 | T23: Global Pharma | U23: =Q23-L23 -> 91.055 | V23: =U23*D23 -> 9105.5 | W23: =Q23-H23 -> 86.1 | X23: =W23*D23 -> 8610 | Z23: =Q23*D23 -> 31360 | AA23: 29400 | AB23: =L23*D23 -> 22254.5 | AC23: =H23*D23 -> 22750
A24: 22 | B24: 7101004 | C24: VOLUMETRIC PIPETTE 4ML CLASS "A"USP | D24: 100 | E24: 350 | F24: 0.35 | G24: =E24*F24 -> 122.5 | H24: =E24-G24 -> 227.5 | I24: 473.5 | J24: 0.53 | K24: =I24*J24 -> 250.955 | L24: =I24-K24 -> 222.545 | M24: =(L24-H24)*100/L24 -> -2.226516 | N24: 490 | O24: 0.36 | P24: =N24*O24 -> 176.4 | Q24: =N24-P24 -> 313.6 | R24: =(Q24-H24)*100/Q24 -> 27.455357 | S24: =MIN(H24,L24,Q24) -> 222.545 | T24: Global Pharma | U24: =Q24-L24 -> 91.055 | V24: =U24*D24 -> 9105.5 | W24: =Q24-H24 -> 86.1 | X24: =W24*D24 -> 8610 | Z24: =Q24*D24 -> 31360 | AA24: 29400 | AB24: =L24*D24 -> 22254.5 | AC24: =H24*D24 -> 22750
A25: 23 | B25: 7101005 | C25: VOLUMETRIC PIPETTE 5ML CLASS "A"USP | D25: 100 | E25: 340 | F25: 0.35 | G25: =E25*F25 -> 119 | H25: =E25-G25 -> 221 | I25: 473.3 | J25: 0.53 | K25: =I25*J25 -> 250.849 | L25: =I25-K25 -> 222.451 | M25: =(L25-H25)*100/L25 -> 0.65227848 | N25: 495 | O25: 0.36 | P25: =N25*O25 -> 178.2 | Q25: =N25-P25 -> 316.8 | R25: =(Q25-H25)*100/Q25 -> 30.239899 | S25: =MIN(H25,L25,Q25) -> 221 | T25: Global Pharma | U25: =Q25-L25 -> 94.349 | V25: =U25*D25 -> 9434.9 | W25: =Q25-H25 -> 95.8 | X25: =W25*D25 -> 9580 | Z25: =Q25*D25 -> 31680 | AA25: 29700 | AB25: =L25*D25 -> 22245.1 | AC25: =H25*D25 -> 22100
A26: 24 | B26: 7101706 | C26: VOLUMETRIC PIPETTE 6ML CLASS "A"USP | D26: 100 | E26: 390 | F26: 0.35 | G26: =E26*F26 -> 136.5 | H26: =E26-G26 -> 253.5 | I26: 520.2 | J26: 0.53 | K26: =I26*J26 -> 275.706 | L26: =I26-K26 -> 244.494 | M26: =(L26-H26)*100/L26 -> -3.683526 | N26: 540 | O26: 0.36 | P26: =N26*O26 -> 194.4 | Q26: =N26-P26 -> 345.6 | R26: =(Q26-H26)*100/Q26 -> 26.649306 | S26: =MIN(H26,L26,Q26) -> 244.494 | T26: Global Pharma | U26: =Q26-L26 -> 101.106 | V26: =U26*D26 -> 10110.6 | W26: =Q26-H26 -> 92.1 | X26: =W26*D26 -> 9210 | Z26: =Q26*D26 -> 34560 | AA26: 32400 | AB26: =L26*D26 -> 24449.4 | AC26: =H26*D26 -> 25350
A27: 25 | B27: 7101707 | C27: VOLUMETRIC PIPETTE 7ML CLASS "A"USP | D27: 100 | E27: 390 | F27: 0.35 | G27: =E27*F27 -> 136.5 | H27: =E27-G27 -> 253.5 | I27: 520.2 | J27: 0.53 | K27: =I27*J27 -> 275.706 | L27: =I27-K27 -> 244.494 | M27: =(L27-H27)*100/L27 -> -3.683526 | N27: 540 | O27: 0.36 | P27: =N27*O27 -> 194.4 | Q27: =N27-P27 -> 345.6 | R27: =(Q27-H27)*100/Q27 -> 26.649306 | S27: =MIN(H27,L27,Q27) -> 244.494 | T27: Global Pharma | U27: =Q27-L27 -> 101.106 | V27: =U27*D27 -> 10110.6 | W27: =Q27-H27 -> 92.1 | X27: =W27*D27 -> 9210 | Z27: =Q27*D27 -> 34560 | AA27: 32400 | AB27: =L27*D27 -> 24449.4 | AC27: =H27*D27 -> 25350
A28: 26 | B28: 7101708 | C28: VOLUMETRIC PIPETTE 8ML CLASS "A"USP | D28: 100 | E28: 390 | F28: 0.35 | G28: =E28*F28 -> 136.5 | H28: =E28-G28 -> 253.5 | I28: 520.2 | J28: 0.53 | K28: =I28*J28 -> 275.706 | L28: =I28-K28 -> 244.494 | M28: =(L28-H28)*100/L28 -> -3.683526 | N28: 540 | O28: 0.36 | P28: =N28*O28 -> 194.4 | Q28: =N28-P28 -> 345.6 | R28: =(Q28-H28)*100/Q28 -> 26.649306 | S28: =MIN(H28,L28,Q28) -> 244.494 | T28: Global Pharma | U28: =Q28-L28 -> 101.106 | V28: =U28*D28 -> 10110.6 | W28: =Q28-H28 -> 92.1 | X28: =W28*D28 -> 9210 | Z28: =Q28*D28 -> 34560 | AA28: 32400 | AB28: =L28*D28 -> 24449.4 | AC28: =H28*D28 -> 25350
A29: 27 | B29: 7101709 | C29: VOLUMETRIC PIPETTE 9ML CLASS "A"USP | D29: 100 | E29: 390 | F29: 0.35 | G29: =E29*F29 -> 136.5 | H29: =E29-G29 -> 253.5 | I29: 520.2 | J29: 0.53 | K29: =I29*J29 -> 275.706 | L29: =I29-K29 -> 244.494 | M29: =(L29-H29)*100/L29 -> -3.683526 | N29: 540 | O29: 0.36 | P29: =N29*O29 -> 194.4 | Q29: =N29-P29 -> 345.6 | R29: =(Q29-H29)*100/Q29 -> 26.649306 | S29: =MIN(H29,L29,Q29) -> 244.494 | T29: Global Pharma | U29: =Q29-L29 -> 101.106 | V29: =U29*D29 -> 10110.6 | W29: =Q29-H29 -> 92.1 | X29: =W29*D29 -> 9210 | Z29: =Q29*D29 -> 34560 | AA29: 32400 | AB29: =L29*D29 -> 24449.4 | AC29: =H29*D29 -> 25350
A30: 28 | B30: 7101006 | C30: VOLUMETRIC PIPETTE 10ML CLASS "A"USP | D30: 100 | E30: 390 | F30: 0.35 | G30: =E30*F30 -> 136.5 | H30: =E30-G30 -> 253.5 | I30: 536.4 | J30: 0.53 | K30: =I30*J30 -> 284.292 | L30: =I30-K30 -> 252.108 | M30: =(L30-H30)*100/L30 -> -0.55214432 | N30: 560 | O30: 0.36 | P30: =N30*O30 -> 201.6 | Q30: =N30-P30 -> 358.4 | R30: =(Q30-H30)*100/Q30 -> 29.268973 | S30: =MIN(H30,L30,Q30) -> 252.108 | T30: Global Pharma | U30: =Q30-L30 -> 106.292 | V30: =U30*D30 -> 10629.2 | W30: =Q30-H30 -> 104.9 | X30: =W30*D30 -> 10490 | Z30: =Q30*D30 -> 35840 | AA30: 33600 | AB30: =L30*D30 -> 25210.8 | AC30: =H30*D30 -> 25350
A31: 29 | B31: 7101007 | C31: VOLUMETRIC PIPETTE 15ML CLASS "A"USP | D31: 100 | E31: 425 | F31: 0.35 | G31: =E31*F31 -> 148.75 | H31: =E31-G31 -> 276.25 | I31: 609.6 | J31: 0.53 | K31: =I31*J31 -> 323.088 | L31: =I31-K31 -> 286.512 | M31: =(L31-H31)*100/L31 -> 3.5816999 | N31: 635 | O31: 0.36 | P31: =N31*O31 -> 228.6 | Q31: =N31-P31 -> 406.4 | R31: =(Q31-H31)*100/Q31 -> 32.025098 | S31: =MIN(H31,L31,Q31) -> 276.25 | T31: Global Pharma | U31: =Q31-L31 -> 119.888 | V31: =U31*D31 -> 11988.8 | W31: =Q31-H31 -> 130.15 | X31: =W31*D31 -> 13015 | Z31: =Q31*D31 -> 40640 | AA31: 38100 | AB31: =L31*D31 -> 28651.2 | AC31: =H31*D31 -> 27625
... A35: 33 | B35: 7101012 | C35: GLASS BEAKER 25ML | D35: 100 | E35: 90 | F35: 0.35 | G35: =E35*F35 -> 31.5 | H35: =E35-G35 -> 58.5 | I35: 138.2 | J35: 0.53 | K35: =I35*J35 -> 73.246 | L35: =I35-K35 -> 64.954 | M35: =(L35-H35)*100/L35 -> 9.9362626 | N35: 145 | O35: 0.36 | P35: =N35*O35 -> 52.2 | Q35: =N35-P35 -> 92.8 | R35: =(Q35-H35)*100/Q35 -> 36.961207 | S35: =MIN(H35,L35,Q35) -> 58.5 | T35: Santosh Enterprises | U35: =Q35-L35 -> 27.846 | V35: =U35*D35 -> 2784.6 | W35: =Q35-H35 -> 34.3 | X35: =W35*D35 -> 3430 | Z35: =Q35*D35 -> 9280 | AA35: 8700 | AB35: =L35*D35 -> 6495.4 | AC35: =H35*D35 -> 5850
A36: 34 | B36: 1000D12 | C36: GLASS BEAKER 50ML | D36: 145 | E36: 72 | F36: 0.35 | G36: =E36*F36 -> 25.2 | H36: =E36-G36 -> 46.8 | I36: 96.1 | J36: 0.53 | K36: =I36*J36 -> 50.933 | L36: =I36-K36 -> 45.167 | M36: =(L36-H36)*100/L36 -> -3.6154715 | N36: 100 | O36: 0.36 | P36: =N36*O36 -> 36 | Q36: =N36-P36 -> 64 | R36: =(Q36-H36)*100/Q36 -> 26.875 | S36: =MIN(H36,L36,Q36) -> 45.167 | T36: Global Pharma | U36: =Q36-L36 -> 18.833 | V36: =U36*D36 -> 2730.785 | W36: =Q36-H36 -> 17.2 | X36: =W36*D36 -> 2494 | Z36: =Q36*D36 -> 9280 | AA36: 8700 | AB36: =L36*D36 -> 6549.215 | AC36: =H36*D36 -> 6786
A37: 35 | B37: 1000D16 | C37: GLASS BEAKER 100ML | D37: 132 | E37: 78 | F37: 0.35 | G37: =E37*F37 -> 27.3 | H37: =E37-G37 -> 50.7 | I37: 99.5 | J37: 0.53 | K37: =I37*J37 -> 52.735 | L37: =I37-K37 -> 46.765 | M37: =(L37-H37)*100/L37 -> -8.4144125 | N37: 100 | O37: 0.36 | P37: =N37*O37 -> 36 | Q37: =N37-P37 -> 64 | R37: =(Q37-H37)*100/Q37 -> 20.78125 | S37: =MIN(H37,L37,Q37) -> 46.765 | T37: Global Pharma | U37: =Q37-L37 -> 17.235 | V37: =U37*D37 -> 2275.02 | W37: =Q37-H37 -> 13.3 | X37: =W37*D37 -> 1755.6 | Z37: =Q37*D37 -> 8448 | AA37: 7920 | AB37: =L37*D37 -> 6172.98 | AC37: =H37*D37 -> 6692.4
A38: 36 | B38: 1000D21 | C38: GLASS BEAKER 250ML | D38: 155 | E38: 100 | F38: 0.35 | G38: =E38*F38 -> 35 | H38: =E38-G38 -> 65 | I38: 109.5 | J38: 0.53 | K38: =I38*J38 -> 58.035 | L38: =I38-K38 -> 51.465 | M38: =(L38-H38)*100/L38 -> -26.299427 | N38: 110 | O38: 0.36 | P38: =N38*O38 -> 39.6 | Q38: =N38-P38 -> 70.4 | R38: =(Q38-H38)*100/Q38 -> 7.6704545 | S38: =MIN(H38,L38,Q38) -> 51.465 | T38: Global Pharma | U38: =Q38-L38 -> 18.935 | V38: =U38*D38 -> 2934.925 | W38: =Q38-H38 -> 5.4 | X38: =W38*D38 -> 837 | Z38: =Q38*D38 -> 10912 | AA38: 10230 | AB38: =L38*D38 -> 7977.075 | AC38: =H38*D38 -> 10075
A39: 37 | B39: 1000D24 | C39: GLASS BEAKER 500ML | D39: 183 | E39: 150 | F39: 0.35 | G39: =E39*F39 -> 52.5 | H39: =E39-G39 -> 97.5 | I39: 174.12 | J39: 0.53 | K39: =I39*J39 -> 92.2836 | L39: =I39-K39 -> 81.8364 | M39: =(L39-H39)*100/L39 -> -19.140138 | N39: 175 | O39: 0.36 | P39: =N39*O39 -> 63 | Q39: =N39-P39 -> 112 | R39: =(Q39-H39)*100/Q39 -> 12.946429 | S39: =MIN(H39,L39,Q39) -> 81.8364 | T39: Global Pharma | U39: =Q39-L39 -> 30.1636 | V39: =U39*D39 -> 5519.9388 | W39: =Q39-H39 -> 14.5 | X39: =W39*D39 -> 2653.5 | Z39: =Q39*D39 -> 20496 | AA39: 19215 | AB39: =L39*D39 -> 14976.061 | AC39: =H39*D39 -> 17842.5
A40: 38 | B40: 1000D29 | C40: GLASS BEAKER 1000ML | D40: 100 | E40: 345 | F40: 0.35 | G40: =E40*F40 -> 120.75 | H40: =E40-G40 -> 224.25 | I40: 353.16 | J40: 0.53 | K40: =I40*J40 -> 187.1748 | L40: =I40-K40 -> 165.9852 | M40: =(L40-H40)*100/L40 -> -35.102407 | N40: 355 | O40: 0.36 | P40: =N40*O40 -> 127.8 | Q40: =N40-P40 -> 227.2 | R40: =(Q40-H40)*100/Q40 -> 1.2984155 | S40: =MIN(H40,L40,Q40) -> 165.9852 | T40: Global Pharma | U40: =Q40-L40 -> 61.2148 | V40: =U40*D40 -> 6121.48 | W40: =Q40-H40 -> 2.95 | X40: =W40*D40 -> 295 | Z40: =Q40*D40 -> 22720 | AA40: 21300 | AB40: =L40*D40 -> 16598.52 | AC40: =H40*D40 -> 22425
A41: 39 | B41: 1501016 | C41: SCREW CAP BOTTLE 100ML | D41: 100 | E41: 345 | F41: 0.35 | G41: =E41*F41 -> 120.75 | H41: =E41-G41 -> 224.25 | I41: 403 | J41: 0.53 | K41: =I41*J41 -> 213.59 | L41: =I41-K41 -> 189.41 | M41: =(L41-H41)*100/L41 -> -18.39396 | N41: 405 | O41: 0.36 | P41: =N41*O41 -> 145.8 | Q41: =N41-P41 -> 259.2 | R41: =(Q41-H41)*100/Q41 -> 13.483796 | S41: =MIN(H41,L41,Q41) -> 189.41 | T41: Global Pharma | U41: =Q41-L41 -> 69.79 | V41: =U41*D41 -> 6979 | W41: =Q41-H41 -> 34.95 | X41: =W41*D41 -> 3495 | Z41: =Q41*D41 -> 25920 | AA41: 24300 | AB41: =L41*D41 -> 18941 | AC41: =H41*D41 -> 22425
A42: 40 | B42: 1501021 | C42: SCREW CAP BOTTLE 250ML | D42: 100 | E42: 370 | F42: 0.35 | G42: =E42*F42 -> 129.5 | H42: =E42-G42 -> 240.5 | I42: 408 | J42: 0.53 | K42: =I42*J42 -> 216.24 | L42: =I42-K42 -> 191.76 | M42: =(L42-H42)*100/L42 -> -25.417188 | N42: 410 | O42: 0.36 | P42: =N42*O42 -> 147.6 | Q42: =N42-P42 -> 262.4 | R42: =(Q42-H42)*100/Q42 -> 8.3460366 | S42: =MIN(H42,L42,Q42) -> 191.76 | T42: Global Pharma | U42: =Q42-L42 -> 70.64 | V42: =U42*D42 -> 7064 | W42: =Q42-H42 -> 21.9 | X42: =W42*D42 -> 2190 | Z42: =Q42*D42 -> 26240 | AA42: 24600 | AB42: =L42*D42 -> 19176 | AC42: =H42*D42 -> 24050
A43: 41 | B43: 1501024 | C43: SCREW CAP BOTTLE 500ML | D43: 100 | E43: 425 | F43: 0.35 | G43: =E43*F43 -> 148.75 | H43: =E43-G43 -> 276.25 | I43: 447.8 | J43: 0.53 | K43: =I43*J43 -> 237.334 | L43: =I43-K43 -> 210.466 | M43: =(L43-H43)*100/L43 -> -31.256355 | N43: 450 | O43: 0.36 | P43: =N43*O43 -> 162 | Q43: =N43-P43 -> 288 | R43: =(Q43-H43)*100/Q43 -> 4.0798611 | S43: =MIN(H43,L43,Q43) -> 210.466 | T43: Global Pharma | U43: =Q43-L43 -> 77.534 | V43: =U43*D43 -> 7753.4 | W43: =Q43-H43 -> 11.75 | X43: =W43*D43 -> 1175 | Z43: =Q43*D43 -> 28800 | AA43: 27000 | AB43: =L43*D43 -> 21046.6 | AC43: =H43*D43 -> 27625
...
